<?xml version="1.0" ?>
<!-- =================================================================================== -->
<!-- |    This document was autogenerated by xacro from src/mower_bot_description/urdf/robot.urdf.xacro | -->
<!-- |    EDITING THIS FILE BY HAND IS NOT RECOMMENDED                                 | -->
<!-- =================================================================================== -->
<robot name="tracked_mower">
  <link name="base_footprint"/>
  <joint name="base_joint" type="fixed">
    <parent link="base_footprint"/>
    <child link="base_link"/>
    <origin rpy="0 0 0" xyz="0 0 0.15"/>
  </joint>
  <link name="base_link">
    <visual name="base_visual">
      <origin xyz="0 0 0"/>
      <geometry>
        <!--box size="${base_x} ${base_y} ${base_z}"/-->
        <mesh filename="package://mower_bot_description/meshes/Car.stl"/>
      </geometry>
      <material name="color">
        <color rgba="0.1 0.6 1.0 1.0"/>
      </material>
    </visual>
    <collision>
      <geometry>
        <box size="0.5 0.24 0.14"/>
      </geometry>
    </collision>
    <inertial>
      <mass value="13.14"/>
      <inertia ixx="0.084534" ixy="0" ixz="0" iyy="0.295212" iyz="0" izz="0.33682199999999995"/>
    </inertial>
  </link>
  <link name="front_left_wheel">
    <visual>
      <geometry>
        <cylinder length="0.05" radius="0.05"/>
      </geometry>
      <material name="transparent">
        <color rgba="0 0 1 0.3"/>
      </material>
    </visual>
    <collision>
      <geometry>
        <sphere radius="0.05"/>
      </geometry>
      <surface>
        <friction>
          <ode>
            <mu>0.0</mu>
            <mu2>0.0</mu2>
            <slip1>1.0</slip1>
            <slip2>1.0</slip2>
          </ode>
        </friction>
      </surface>
    </collision>
    <inertial>
      <mass value="0.5"/>
      <inertia ixx="0.001" ixy="0" ixz="0" iyy="0.001" iyz="0" izz="0.001"/>
    </inertial>
  </link>
  <joint name="front_left_wheel_joint" type="continuous">
    <parent link="base_link"/>
    <child link="front_left_wheel"/>
    <origin rpy="-1.5708 0 0" xyz="0.2 0.2 -0.1"/>
    <axis xyz="0 0 1"/>
  </joint>
  <link name="mid_left_wheel">
    <visual>
      <geometry>
        <cylinder length="0.05" radius="0.05"/>
      </geometry>
      <material name="transparent">
        <color rgba="0 0 1 0.3"/>
      </material>
    </visual>
    <collision>
      <geometry>
        <sphere radius="0.05"/>
      </geometry>
      <surface>
        <friction>
          <ode>
            <mu>0.0</mu>
            <mu2>0.0</mu2>
            <slip1>1.0</slip1>
            <slip2>1.0</slip2>
          </ode>
        </friction>
      </surface>
    </collision>
    <inertial>
      <mass value="0.5"/>
      <inertia ixx="0.001" ixy="0" ixz="0" iyy="0.001" iyz="0" izz="0.001"/>
    </inertial>
  </link>
  <joint name="mid_left_wheel_joint" type="continuous">
    <parent link="base_link"/>
    <child link="mid_left_wheel"/>
    <origin rpy="-1.5708 0 0" xyz="0.0 0.2 -0.1"/>
    <axis xyz="0 0 1"/>
  </joint>
  <link name="rear_left_wheel">
    <visual>
      <geometry>
        <cylinder length="0.05" radius="0.05"/>
      </geometry>
      <material name="transparent">
        <color rgba="1 0 0 0.3"/>
      </material>
    </visual>
    <collision>
      <geometry>
        <cylinder length="0.05" radius="0.05"/>
      </geometry>
      <surface>
        <friction>
          <ode>
            <mu>2.0</mu>
            <mu2>0.5</mu2>
            <fdir1>1 0 0</fdir1>
            <slip1>0.0</slip1>
            <slip2>0.0</slip2>
          </ode>
        </friction>
        <contact>
          <ode>
            <kp>10000000.0</kp>
            <kd>1.0</kd>
          </ode>
        </contact>
      </surface>
    </collision>
    <inertial>
      <mass value="2.0"/>
      <inertia ixx="0.01" ixy="0" ixz="0" iyy="0.01" iyz="0" izz="0.01"/>
    </inertial>
  </link>
  <joint name="rear_left_wheel_joint" type="continuous">
    <parent link="base_link"/>
    <child link="rear_left_wheel"/>
    <origin rpy="-1.5708 0 0" xyz="-0.2 0.2 -0.1"/>
    <axis xyz="0 0 1"/>
  </joint>
  <link name="front_right_wheel">
    <visual>
      <geometry>
        <cylinder length="0.05" radius="0.05"/>
      </geometry>
      <material name="transparent">
        <color rgba="0 0 1 0.3"/>
      </material>
    </visual>
    <collision>
      <geometry>
        <sphere radius="0.05"/>
      </geometry>
      <surface>
        <friction>
          <ode>
            <mu>0.0</mu>
            <mu2>0.0</mu2>
            <slip1>1.0</slip1>
            <slip2>1.0</slip2>
          </ode>
        </friction>
      </surface>
    </collision>
    <inertial>
      <mass value="0.5"/>
      <inertia ixx="0.001" ixy="0" ixz="0" iyy="0.001" iyz="0" izz="0.001"/>
    </inertial>
  </link>
  <joint name="front_right_wheel_joint" type="continuous">
    <parent link="base_link"/>
    <child link="front_right_wheel"/>
    <origin rpy="-1.5708 0 0" xyz="0.2 -0.2 -0.1"/>
    <axis xyz="0 0 1"/>
  </joint>
  <link name="mid_right_wheel">
    <visual>
      <geometry>
        <cylinder length="0.05" radius="0.05"/>
      </geometry>
      <material name="transparent">
        <color rgba="0 0 1 0.3"/>
      </material>
    </visual>
    <collision>
      <geometry>
        <sphere radius="0.05"/>
      </geometry>
      <surface>
        <friction>
          <ode>
            <mu>0.0</mu>
            <mu2>0.0</mu2>
            <slip1>1.0</slip1>
            <slip2>1.0</slip2>
          </ode>
        </friction>
      </surface>
    </collision>
    <inertial>
      <mass value="0.5"/>
      <inertia ixx="0.001" ixy="0" ixz="0" iyy="0.001" iyz="0" izz="0.001"/>
    </inertial>
  </link>
  <joint name="mid_right_wheel_joint" type="continuous">
    <parent link="base_link"/>
    <child link="mid_right_wheel"/>
    <origin rpy="-1.5708 0 0" xyz="0.0 -0.2 -0.1"/>
    <axis xyz="0 0 1"/>
  </joint>
  <link name="rear_right_wheel">
    <visual>
      <geometry>
        <cylinder length="0.05" radius="0.05"/>
      </geometry>
      <material name="transparent">
        <color rgba="1 0 0 0.3"/>
      </material>
    </visual>
    <collision>
      <geometry>
        <cylinder length="0.05" radius="0.05"/>
      </geometry>
      <surface>
        <friction>
          <ode>
            <mu>2.0</mu>
            <mu2>0.5</mu2>
            <fdir1>1 0 0</fdir1>
            <slip1>0.0</slip1>
            <slip2>0.0</slip2>
          </ode>
        </friction>
        <contact>
          <ode>
            <kp>10000000.0</kp>
            <kd>1.0</kd>
          </ode>
        </contact>
      </surface>
    </collision>
    <inertial>
      <mass value="2.0"/>
      <inertia ixx="0.01" ixy="0" ixz="0" iyy="0.01" iyz="0" izz="0.01"/>
    </inertial>
  </link>
  <joint name="rear_right_wheel_joint" type="continuous">
    <parent link="base_link"/>
    <child link="rear_right_wheel"/>
    <origin rpy="-1.5708 0 0" xyz="-0.2 -0.2 -0.1"/>
    <axis xyz="0 0 1"/>
  </joint>
  <link name="left_track_visual">
    <visual>
      <geometry>
        <box size="0.5 0.1 0.18"/>
      </geometry>
      <material name="black">
        <color rgba="0.1 0.1 0.1 1.0"/>
      </material>
    </visual>
    <collision>
      <origin xyz="0 0 0.05"/>
      <geometry>
        <box size="0.5 0.1 0.15"/>
      </geometry>
    </collision>
    <inertial>
      <mass value="2.0"/>
      <inertia ixx="0.01" ixy="0" ixz="0" iyy="0.01" iyz="0" izz="0.01"/>
    </inertial>
  </link>
  <joint name="left_track_joint" type="fixed">
    <parent link="base_link"/>
    <child link="left_track_visual"/>
    <origin rpy="0 0 0" xyz="0 0.2 0"/>
  </joint>
  <link name="right_track_visual">
    <visual>
      <geometry>
        <box size="0.5 0.1 0.18"/>
      </geometry>
      <material name="black">
        <color rgba="0.1 0.1 0.1 1.0"/>
      </material>
    </visual>
    <collision>
      <origin xyz="0 0 0.05"/>
      <geometry>
        <box size="0.5 0.1 0.15"/>
      </geometry>
    </collision>
    <inertial>
      <mass value="2.0"/>
      <inertia ixx="0.01" ixy="0" ixz="0" iyy="0.01" iyz="0" izz="0.01"/>
    </inertial>
  </link>
  <joint name="right_track_joint" type="fixed">
    <parent link="base_link"/>
    <child link="right_track_visual"/>
    <origin rpy="0 0 0" xyz="0 -0.2 0"/>
  </joint>
  <link name="lidar_link">
    <visual>
      <geometry>
        <cylinder length="0.04" radius="0.05"/>
      </geometry>
      <material name="red">
        <color rgba="1 0 0 1.0"/>
      </material>
    </visual>
    <collision>
      <geometry>
        <cylinder length="0.04" radius="0.05"/>
      </geometry>
    </collision>
    <inertial>
      <mass value="0.1"/>
      <inertia ixx="0.0001" ixy="0" ixz="0" iyy="0.0001" iyz="0" izz="0.0001"/>
    </inertial>
  </link>
  <joint name="lidar_mount_joint" type="fixed">
    <parent link="base_link"/>
    <child link="lidar_link"/>
    <origin rpy="0 0 0" xyz="0.1 0 0.15"/>
  </joint>
  <link name="laser_frame">
    <visual>
      <geometry>
        <box size="0.01 0.01 0.01"/>
      </geometry>
      <material name="black"/>
    </visual>
  </link>
  <joint name="laser_joint" type="fixed">
    <parent link="lidar_link"/>
    <child link="laser_frame"/>
    <origin rpy="0 0 0" xyz="0 0 0.03"/>
  </joint>
  <link name="imu_link"/>
  <joint name="imu_joint" type="fixed">
    <parent link="base_link"/>
    <child link="imu_link"/>
    <origin rpy="0 0 0" xyz="0 0 0"/>
  </joint>
  <gazebo reference="left_track_visual">
    <material>Gazebo/DarkGrey</material>
  </gazebo>
  <gazebo reference="right_track_visual">
    <material>Gazebo/DarkGrey</material>
  </gazebo>
  <gazebo reference="lidar_link">
    <material>Gazebo/Red</material>
  </gazebo>
  <gazebo reference="base_link">
    <visual>
      <material>
        <script>
          <uri>file://media/materials/scripts/gazebo.material</uri>
          <name>Gazebo/Orange</name>
        </script>
        <ambient>1.0 0.5 0.0 1.0</ambient>
        <diffuse>1.0 0.5 0.0 1.0</diffuse>
        <specular>0.1 0.1 0.1 1.0</specular>
        <emissive>0.0 0.0 0.0 0.0</emissive>
      </material>
    </visual>
  </gazebo>
  <gazebo>
    <plugin filename="libgazebo_ros_diff_drive.so" name="diff_drive">
      <ros>
        <namespace>/</namespace>
      </ros>
      <num_wheel_pairs>2</num_wheel_pairs>
      <left_joint>front_left_wheel_joint</left_joint>
      <left_joint>rear_left_wheel_joint</left_joint>
      <right_joint>front_right_wheel_joint</right_joint>
      <right_joint>rear_right_wheel_joint</right_joint>
      <wheel_separation>0.4</wheel_separation>
      <wheel_diameter>0.1</wheel_diameter>
      <max_wheel_torque>100</max_wheel_torque>
      <max_wheel_acceleration>2.0</max_wheel_acceleration>
      <publish_odom>true</publish_odom>
      <publish_odom_tf>true</publish_odom_tf>
      <publish_wheel_tf>false</publish_wheel_tf>
      <odometry_frame>odom</odometry_frame>
      <robot_base_frame>base_footprint</robot_base_frame>
    </plugin>
    <plugin filename="libgazebo_ros_joint_state_publisher.so" name="joint_state">
      <ros>
        <remapping>~/out:=joint_states</remapping>
      </ros>
      <update_rate>30</update_rate>
    </plugin>
  </gazebo>
  <gazebo reference="imu_link">
    <sensor name="imu_sensor" type="imu">
      <plugin filename="libgazebo_ros_imu_sensor.so" name="imu_plugin">
        <ros>
          <argument>~/out:=imu</argument>
        </ros>
        <frame_name>imu_link</frame_name>
      </plugin>
      <always_on>true</always_on>
      <update_rate>100</update_rate>
    </sensor>
  </gazebo>
  <gazebo reference="laser_frame">
    <sensor name="lidar" type="ray">
      <pose> 0 0 0 0 0 0 </pose>
      <always_on>true</always_on>
      <visualize>false</visualize>
      <!-- เปิด/ปิดเส้นlaser lidar-->
      <update_rate>10</update_rate>
      <ray>
        <scan>
          <horizontal>
            <samples>360</samples>
            <min_angle>-3.14</min_angle>
            <max_angle>3.14</max_angle>
          </horizontal>
        </scan>
        <range>
          <min>0.1</min>
          <max>12.0</max>
        </range>
      </ray>
      <plugin filename="libgazebo_ros_ray_sensor.so" name="laser_controller">
        <ros>
          <argument>~/out:=scan</argument>
        </ros>
        <output_type>sensor_msgs/LaserScan</output_type>
        <frame_name>laser_frame</frame_name>
      </plugin>
    </sensor>
  </gazebo>
</robot>
